<?xml version="1.0" encoding="UTF-8"?>
<mujoco model="chessboard_ground">
    <option gravity="0 0 -9.81" timestep="0.25" />

    <asset>
        <!-- Texture scacchiera blu chiaro e blu scuro -->
        <texture name="chessboard" type="2d" builtin="checker" rgb1="0.6 0.8 1"  rgb2="0.0 0.2 0.4"  width="100" height="100"/>  
        <material name="chessboard_material" texture="chessboard" texrepeat="1 1" texuniform="true"/>
        <material name="sphere_material" rgba="1 0.2 0.2 1"/>
        <material name="cube_material" rgba="0.2 0.2 1 1"/>
        <material name="agent_material" rgba="0 0 0 1"/>
        <material name="wall_material" rgba="0.5 0.5 0.7 1"/>
        <material name="arrow_material" rgba="0 1 0 1"/>

        <mesh name="cylinder_robot" file="cylinder_robot.stl"/>
    </asset>
    
    <worldbody>
        <geom name="ground" type="plane" size="50 50 0.1" pos="0 0 0" material="chessboard_material"/>

        <light name="light1" pos="0 0 500" dir="0 0 -1" diffuse="0.8 0.8 0.8" specular="0.1 0.1 0.1" castshadow="true"/>
        
        <body name="cube_body" pos="0 0 0.5">
            <!-- <geom name="cube" type="mesh" mesh="cylinder_robot" material="arrow_material" /> -->
            <geom name="cube" type="cylinder" size="0.32 0.8" mass="1.0" material="agent_material" contype="0" conaffinity="0"/> 
            <joint name="slider_x" type="slide" axis="1 0 0"/>
            <joint name="slider_y" type="slide" axis="0 1 0"/>
            <joint name="hinge_z" type="hinge" axis="0 0 1"/>
            
    
        </body>
    
        <geom name="sphere" type="sphere" size="1" pos="0 0 10" material="sphere_material"/>
        <geom name="wall_north" type="box" size="17.5 0.5 2" pos="0 17.5 2" material="wall_material"/>
        <geom name="wall_south" type="box" size="17.5 0.5 2" pos="0 -17.5 2" material="wall_material"/>
        <geom name="wall_east" type="box" size="0.5 17.5 2" pos="17.5 0 2" material="wall_material"/>
        <geom name="wall_west" type="box" size="0.5 17.5 2" pos="-17.5 0 2" material="wall_material"/>
        <body name="obstacle1" pos="2 2 1">
            <geom name="obstacle1" type="box" size="1 1 1" mass="1.0" material="cube_material" contype="1" conaffinity="1"/>
        </body>

        <body name="obstacle2" pos="-2 2 1">
            <geom name="obstacle2" type="box" size="1 1 1" mass="1.0" material="cube_material" contype="1" conaffinity="1"/>
        </body>

        <body name="obstacle3" pos="2 -2 1">
            <geom name="obstacle3" type="box" size="1 1 1" mass="1.0" material="cube_material" contype="1" conaffinity="1"/>
        </body>

        <body name="obstacle4" pos="-2 -2 1">
            <geom name="obstacle4" type="box" size="1 1 1" mass="1.0" material="cube_material" contype="1" conaffinity="1"/>
        </body>

        <body name="obstacle5" pos="3 0 1">
            <geom name="obstacle5" type="box" size="1 1 1" mass="1.0" material="cube_material" contype="1" conaffinity="1"/>
        </body>

        <body name="obstacle6" pos="4 0 1">
            <geom name="obstacle6" type="box" size="1 1 1" mass="1.0" material="cube_material" contype="1" conaffinity="1"/>
        </body>

        <body name="obstacle7" pos="5 5 1">
            <geom name="obstacle7" type="box" size="1 1 1" mass="1.0" material="cube_material" contype="1" conaffinity="1"/>
        </body>

        <body name="obstacle8" pos="3 7 1">
            <geom name="obstacle8" type="box" size="1 1 1" mass="1.0" material="cube_material" contype="1" conaffinity="1"/>
        </body>

        <body name="obstacle9" pos="0 7 1">
            <geom name="obstacle9" type="box" size="1 1 1" mass="1.0" material="cube_material" contype="1" conaffinity="1"/>
        </body>

        <body name="obstacle10" pos="9 0 1">
            <geom name="obstacle10" type="box" size="1 1 1" mass="1.0" material="cube_material" contype="1" conaffinity="1"/>       
        </body>

        <body name="obstacle11" pos="10 2 1">
            <geom name="obstacle11" type="box" size="1 1 1" mass="1.0" material="cube_material" contype="1" conaffinity="1"/>
        </body>

        <body name="obstacle12" pos="10 -2 1">
            <geom name="obstacle12" type="box" size="1 1 1" mass="1.0" material="cube_material" contype="1" conaffinity="1"/>
        </body>

        <body name="obstacle13" pos="10 5 1">
            <geom name="obstacle13" type="box" size="1 1 1" mass="1.0" material="cube_material" contype="1" conaffinity="1"/>
        </body>

        <body name="obstacle14" pos="10 7 1">
            <geom name="obstacle14" type="box" size="1 1 1" mass="1.0" material="cube_material" contype="1" conaffinity="1"/>
        </body>

        <body name="obstacle15" pos="10 9 1">
            <geom name="obstacle15" type="box" size="1 1 1" mass="1.0" material="cube_material" contype="1" conaffinity="1"/>
        </body>

        <body name="obstacle16" pos="10 11 1">
            <geom name="obstacle16" type="box" size="1 1 1" mass="1.0" material="cube_material" contype="1" conaffinity="1"/>
        </body>

        <body name="obstacle17" pos="10 13 1">
            <geom name="obstacle17" type="box" size="1 1 1" mass="1.0" material="cube_material" contype="1" conaffinity="1"/>
        </body>

        <body name="obstacle18" pos="10 15 1">
            <geom name="obstacle18" type="box" size="1 1 1" mass="1.0" material="cube_material" contype="1" conaffinity="1"/>
        </body>

        <body name="obstacle19" pos="10 17 1">
            <geom name="obstacle19" type="box" size="1 1 1" mass="1.0" material="cube_material" contype="1" conaffinity="1"/>
        </body>

        <body name="obstacle20" pos="10 19 1">
            <geom name="obstacle20" type="box" size="1 1 1" mass="1.0" material="cube_material" contype="1" conaffinity="1"/>
        </body>

    </worldbody>
    
    <sensor>
       
    </sensor>

    <visual>
        <global offwidth="800" offheight="600"/>
        <quality shadowsize="2048"/>
        <headlight ambient="0.3 0.3 0.3" diffuse="0.7 0.7 0.7" specular="0.1 0.1 0.1"/>
        <map znear="0.01"/>
        <scale forcewidth="0.01" contactwidth="0.05" contactheight="0.05" jointwidth="0.05" framelength="0.2" framewidth="0.02"/>
        <rgba contactpoint="0 0.9 0 0.7" contactforce="0 0.5 0.3 0.1"/>
    </visual>
</mujoco>